2023-09-24 21:29:34.327 WARNING (SyncWorker_3) [homeassistant.loader] We found a custom integration hacs which has not been tested by Home Assistant. This component might cause stability problems, be sure to disable it if you experience issues with Home Assistant
2023-09-24 21:29:34.327 ERROR (SyncWorker_3) [homeassistant.loader] The custom integration 'hacs' does not have a version key in the manifest file and was blocked from loading. See https://developers.home-assistant.io/blog/2021/01/29/custom-integration-changes#versions for more details
2023-09-24 21:29:34.329 WARNING (SyncWorker_3) [homeassistant.loader] We found a custom integration xboxone which has not been tested by Home Assistant. This component might cause stability problems, be sure to disable it if you experience issues with Home Assistant
2023-09-24 21:29:34.330 ERROR (SyncWorker_3) [homeassistant.loader] The custom integration 'xboxone' does not have a version key in the manifest file and was blocked from loading. See https://developers.home-assistant.io/blog/2021/01/29/custom-integration-changes#versions for more details
2023-09-24 21:30:00.393 ERROR (MainThread) [homeassistant.components.plex] The plex integration does not support YAML setup, please remove it from your configuration file
2023-09-24 21:30:02.498 WARNING (MainThread) [homeassistant.components.sensor] Platform epsonworkforce not ready yet: None; Retrying in background in 30 seconds
2023-09-24 21:30:05.241 WARNING (MainThread) [homeassistant.config_entries] Config entry 'EPSON WF-3520 Series' for ipp integration not ready yet: Invalid response from API: Error occurred while communicating with IPP server.; Retrying in background
2023-09-24 21:30:14.910 ERROR (MainThread) [homeassistant.components.device_tracker] Platform mobile_app does not generate unique IDs. ID 0EC8C2CF-F127-432F-A387-769303EBDB29 already exists - ignoring device_tracker.jose_iphone
2023-09-24 21:30:19.438 WARNING (MainThread) [homeassistant.components.vizio.media_player] Lost connection to 192.168.1.27:9000
2023-09-24 21:30:31.271 WARNING (MainThread) [homeassistant.config_entries] Config entry 'Bathroom 1' for lifx integration not ready yet: get_hostfirmware, get_version, get_group timed out after 5 attempts; Retrying in background
2023-09-24 21:30:31.275 WARNING (MainThread) [homeassistant.config_entries] Config entry 'Bathroom 2' for lifx integration not ready yet: get_hostfirmware, get_version, get_group timed out after 5 attempts; Retrying in background
2023-09-24 21:30:31.280 WARNING (MainThread) [homeassistant.config_entries] Config entry 'Fan 1' for lifx integration not ready yet: get_hostfirmware, get_version, get_group timed out after 5 attempts; Retrying in background
2023-09-24 21:30:31.395 WARNING (MainThread) [homeassistant.components.homeassistant.triggers.numeric_state] Error initializing 'Ink Low Notification' trigger: In 'numeric_state' condition: unknown entity sensor.ink_level_black
2023-09-24 21:30:41.481 WARNING (Recorder) [homeassistant.components.sensor.recorder] The unit of sensor.powder_room_multisensor_ultraviolet (UV index) cannot be converted to the unit of previously compiled statistics (None). Generation of long term statistics will be suppressed unless the unit changes back to None or a compatible unit. Go to https://my.home-assistant.io/redirect/developer_statistics to fix this
2023-09-24 21:32:58.577 ERROR (MainThread) [homeassistant.components.xbox] Error requesting xbox data: 503, message='Service Unavailable', url=URL('https://peoplehub.xboxlive.com/users/me/people/batch/decoration/preferredcolor,detail,multiplayersummary,presencedetail')
2023-09-24 21:40:19.820 ERROR (MainThread) [homeassistant.components.openweathermap.weather_update_coordinator] Error fetching openweathermap data: API call timeouted
2023-09-24 21:59:38.148 WARNING (MainThread) [homeassistant.core] Task <Task pending name='call_later 80.073421' coro=<ConfigEntry.async_setup.<locals>.setup_again() running at /usr/src/homeassistant/homeassistant/config_entries.py:457> wait_for=<Future pending cb=[Task.task_wakeup()]> cb=[set.remove()]> was still running after stage 2 shutdown; Integrations should cancel non-critical tasks when receiving the stop event to prevent delaying shutdown
2023-09-24 21:59:38.158 ERROR (MainThread) [homeassistant.config_entries] Error setting up entry Fan 1 for lifx
Traceback (most recent call last):
  File "/usr/src/homeassistant/homeassistant/config_entries.py", line 387, in async_setup
    result = await component.async_setup_entry(hass, self)
             ^^^^^^^^^^^^^^^^^^^^^^^^^^^^^^^^^^^^^^^^^^^^^
  File "/usr/src/homeassistant/homeassistant/components/lifx/__init__.py", line 216, in async_setup_entry
    await coordinator.async_config_entry_first_refresh()
  File "/usr/src/homeassistant/homeassistant/helpers/update_coordinator.py", line 257, in async_config_entry_first_refresh
    await self._async_refresh(
  File "/usr/src/homeassistant/homeassistant/helpers/update_coordinator.py", line 293, in _async_refresh
    self.data = await self._async_update_data()
                ^^^^^^^^^^^^^^^^^^^^^^^^^^^^^^^
  File "/usr/src/homeassistant/homeassistant/components/lifx/coordinator.py", line 267, in _async_update_data
    await self._async_populate_device_info()
  File "/usr/src/homeassistant/homeassistant/components/lifx/coordinator.py", line 207, in _async_populate_device_info
    await async_multi_execute_lifx_with_retries(
  File "/usr/src/homeassistant/homeassistant/components/lifx/util.py", line 224, in async_multi_execute_lifx_with_retries
    _, pending = await asyncio.wait(futures, timeout=timeout_per_attempt)
                 ^^^^^^^^^^^^^^^^^^^^^^^^^^^^^^^^^^^^^^^^^^^^^^^^^^^^^^^^
  File "/usr/local/lib/python3.11/asyncio/tasks.py", line 418, in wait
    return await _wait(fs, timeout, return_when, loop)
           ^^^^^^^^^^^^^^^^^^^^^^^^^^^^^^^^^^^^^^^^^^^
  File "/usr/local/lib/python3.11/asyncio/tasks.py", line 525, in _wait
    await waiter
asyncio.exceptions.CancelledError: Home Assistant stage 2 shutdown
2023-09-24 21:59:38.175 WARNING (MainThread) [homeassistant.core] Task <Task pending name='call_later 80.256747' coro=<ConfigEntry.async_setup.<locals>.setup_again() running at /usr/src/homeassistant/homeassistant/config_entries.py:457> wait_for=<Future pending cb=[Task.task_wakeup()]> cb=[set.remove()]> was still running after stage 2 shutdown; Integrations should cancel non-critical tasks when receiving the stop event to prevent delaying shutdown
2023-09-24 21:59:38.183 ERROR (MainThread) [homeassistant.config_entries] Error setting up entry Bathroom 1 for lifx
Traceback (most recent call last):
  File "/usr/src/homeassistant/homeassistant/config_entries.py", line 387, in async_setup
    result = await component.async_setup_entry(hass, self)
             ^^^^^^^^^^^^^^^^^^^^^^^^^^^^^^^^^^^^^^^^^^^^^
  File "/usr/src/homeassistant/homeassistant/components/lifx/__init__.py", line 216, in async_setup_entry
    await coordinator.async_config_entry_first_refresh()
  File "/usr/src/homeassistant/homeassistant/helpers/update_coordinator.py", line 257, in async_config_entry_first_refresh
    await self._async_refresh(
  File "/usr/src/homeassistant/homeassistant/helpers/update_coordinator.py", line 293, in _async_refresh
    self.data = await self._async_update_data()
                ^^^^^^^^^^^^^^^^^^^^^^^^^^^^^^^
  File "/usr/src/homeassistant/homeassistant/components/lifx/coordinator.py", line 267, in _async_update_data
    await self._async_populate_device_info()
  File "/usr/src/homeassistant/homeassistant/components/lifx/coordinator.py", line 207, in _async_populate_device_info
    await async_multi_execute_lifx_with_retries(
  File "/usr/src/homeassistant/homeassistant/components/lifx/util.py", line 224, in async_multi_execute_lifx_with_retries
    _, pending = await asyncio.wait(futures, timeout=timeout_per_attempt)
                 ^^^^^^^^^^^^^^^^^^^^^^^^^^^^^^^^^^^^^^^^^^^^^^^^^^^^^^^^
  File "/usr/local/lib/python3.11/asyncio/tasks.py", line 418, in wait
    return await _wait(fs, timeout, return_when, loop)
           ^^^^^^^^^^^^^^^^^^^^^^^^^^^^^^^^^^^^^^^^^^^
  File "/usr/local/lib/python3.11/asyncio/tasks.py", line 525, in _wait
    await waiter
asyncio.exceptions.CancelledError: Home Assistant stage 2 shutdown
2023-09-24 21:59:38.190 WARNING (MainThread) [homeassistant.core] Task <Task pending name='call_later 80.128494' coro=<ConfigEntry.async_setup.<locals>.setup_again() running at /usr/src/homeassistant/homeassistant/config_entries.py:457> wait_for=<Future pending cb=[Task.task_wakeup()]> cb=[set.remove()]> was still running after stage 2 shutdown; Integrations should cancel non-critical tasks when receiving the stop event to prevent delaying shutdown
2023-09-24 21:59:38.191 ERROR (MainThread) [homeassistant.config_entries] Error setting up entry Bathroom 2 for lifx
Traceback (most recent call last):
  File "/usr/src/homeassistant/homeassistant/config_entries.py", line 387, in async_setup
    result = await component.async_setup_entry(hass, self)
             ^^^^^^^^^^^^^^^^^^^^^^^^^^^^^^^^^^^^^^^^^^^^^
  File "/usr/src/homeassistant/homeassistant/components/lifx/__init__.py", line 216, in async_setup_entry
    await coordinator.async_config_entry_first_refresh()
  File "/usr/src/homeassistant/homeassistant/helpers/update_coordinator.py", line 257, in async_config_entry_first_refresh
    await self._async_refresh(
  File "/usr/src/homeassistant/homeassistant/helpers/update_coordinator.py", line 293, in _async_refresh
    self.data = await self._async_update_data()
                ^^^^^^^^^^^^^^^^^^^^^^^^^^^^^^^
  File "/usr/src/homeassistant/homeassistant/components/lifx/coordinator.py", line 267, in _async_update_data
    await self._async_populate_device_info()
  File "/usr/src/homeassistant/homeassistant/components/lifx/coordinator.py", line 207, in _async_populate_device_info
    await async_multi_execute_lifx_with_retries(
  File "/usr/src/homeassistant/homeassistant/components/lifx/util.py", line 224, in async_multi_execute_lifx_with_retries
    _, pending = await asyncio.wait(futures, timeout=timeout_per_attempt)
                 ^^^^^^^^^^^^^^^^^^^^^^^^^^^^^^^^^^^^^^^^^^^^^^^^^^^^^^^^
  File "/usr/local/lib/python3.11/asyncio/tasks.py", line 418, in wait
    return await _wait(fs, timeout, return_when, loop)
           ^^^^^^^^^^^^^^^^^^^^^^^^^^^^^^^^^^^^^^^^^^^
  File "/usr/local/lib/python3.11/asyncio/tasks.py", line 525, in _wait
    await waiter
asyncio.exceptions.CancelledError: Home Assistant stage 2 shutdown
